2021-04-16 16:28:19,809 DEBUG    root            Loaded Command Group: ['gcloud', 'container']
2021-04-16 16:28:19,813 DEBUG    root            Loaded Command Group: ['gcloud', 'container', 'clusters']
2021-04-16 16:28:19,819 DEBUG    root            Loaded Command Group: ['gcloud', 'container', 'clusters', 'describe']
2021-04-16 16:28:19,845 DEBUG    google.auth.transport.requests Making request: GET http://metadata.google.internal/computeMetadata/v1/instance/service-accounts/senmioxl@gmail.com/?recursive=true
2021-04-16 16:28:19,848 DEBUG    urllib3.connectionpool Starting new HTTP connection (1): metadata.google.internal:80
2021-04-16 16:28:19,852 DEBUG    urllib3.connectionpool http://metadata.google.internal:80 "GET /computeMetadata/v1/instance/service-accounts/senmioxl@gmail.com/?recursive=true HTTP/1.1" 200 None
2021-04-16 16:28:19,853 DEBUG    google.auth.transport.requests Making request: GET http://metadata.google.internal/computeMetadata/v1/instance/service-accounts/senmioxl@gmail.com/token
2021-04-16 16:28:19,855 DEBUG    urllib3.connectionpool Resetting dropped connection: metadata.google.internal
2021-04-16 16:28:19,858 DEBUG    urllib3.connectionpool http://metadata.google.internal:80 "GET /computeMetadata/v1/instance/service-accounts/senmioxl@gmail.com/token HTTP/1.1" 200 None
2021-04-16 16:28:19,871 DEBUG    google.auth.transport.requests Making request: GET http://metadata.google.internal/computeMetadata/v1/instance/service-accounts/senmioxl@gmail.com/?recursive=true
2021-04-16 16:28:19,874 DEBUG    urllib3.connectionpool Starting new HTTP connection (1): metadata.google.internal:80
2021-04-16 16:28:19,877 DEBUG    urllib3.connectionpool http://metadata.google.internal:80 "GET /computeMetadata/v1/instance/service-accounts/senmioxl@gmail.com/?recursive=true HTTP/1.1" 200 None
2021-04-16 16:28:19,878 DEBUG    google.auth.transport.requests Making request: GET http://metadata.google.internal/computeMetadata/v1/instance/service-accounts/senmioxl@gmail.com/token
2021-04-16 16:28:19,880 DEBUG    urllib3.connectionpool Resetting dropped connection: metadata.google.internal
2021-04-16 16:28:19,883 DEBUG    urllib3.connectionpool http://metadata.google.internal:80 "GET /computeMetadata/v1/instance/service-accounts/senmioxl@gmail.com/token HTTP/1.1" 200 None
2021-04-16 16:28:19,907 DEBUG    root            Running [gcloud.container.clusters.describe] with arguments: [--format: "json", --project: "cohesive-slate-308002", --quiet: "True", --region: "us-east1", NAME: "richard"]
2021-04-16 16:28:20,548 DEBUG    root            (gcloud.container.clusters.describe) ResponseError: code=404, message=Not found: projects/cohesive-slate-308002/locations/us-east1/clusters/richard.
Could not find [richard] in [us-east1].
Did you mean [richard] in [us-east1-b]?
Traceback (most recent call last):
  File "/usr/lib/google-cloud-sdk/lib/googlecloudsdk/api_lib/container/api_adapter.py", line 1091, in GetCluster
    .zone, cluster_ref.clusterId)))
  File "/usr/lib/google-cloud-sdk/lib/googlecloudsdk/third_party/apis/container/v1/container_v1_client.py", line 494, in Get
    config, request, global_params=global_params)
  File "/usr/bin/../lib/google-cloud-sdk/lib/third_party/apitools/base/py/base_api.py", line 731, in _RunMethod
    return self.ProcessHttpResponse(method_config, http_response, request)
  File "/usr/bin/../lib/google-cloud-sdk/lib/third_party/apitools/base/py/base_api.py", line 737, in ProcessHttpResponse
    self.__ProcessHttpResponse(method_config, http_response, request))
  File "/usr/bin/../lib/google-cloud-sdk/lib/third_party/apitools/base/py/base_api.py", line 604, in __ProcessHttpResponse
    http_response, method_config=method_config, request=request)
apitools.base.py.exceptions.HttpNotFoundError: HttpError accessing <https://container.googleapis.com/v1/projects/cohesive-slate-308002/locations/us-east1/clusters/richard?alt=json>: response: <{'vary': 'Origin, X-Origin, Referer', 'content-type': 'application/json; charset=UTF-8', 'date': 'Fri, 16 Apr 2021 16:28:20 GMT', 'server': 'ESF', 'cache-control': 'private', 'x-xss-protection': '0', 'x-frame-options': 'SAMEORIGIN', 'x-content-type-options': 'nosniff', 'transfer-encoding': 'chunked', 'status': '404', 'content-length': '161', '-content-encoding': 'gzip'}>, content <{
  "error": {
    "code": 404,
    "message": "Not found: projects/cohesive-slate-308002/locations/us-east1/clusters/richard.",
    "status": "NOT_FOUND"
  }
}
>

During handling of the above exception, another exception occurred:

Traceback (most recent call last):
  File "/usr/lib/google-cloud-sdk/lib/googlecloudsdk/calliope/cli.py", line 982, in Execute
    resources = calliope_command.Run(cli=self, args=args)
  File "/usr/lib/google-cloud-sdk/lib/googlecloudsdk/calliope/backend.py", line 809, in Run
    resources = command_instance.Run(args)
  File "/usr/lib/google-cloud-sdk/lib/surface/container/clusters/describe.py", line 67, in Run
    c = adapter.GetCluster(adapter.ParseCluster(args.name, location))
  File "/usr/lib/google-cloud-sdk/lib/googlecloudsdk/api_lib/container/api_adapter.py", line 1095, in GetCluster
    self.CheckClusterOtherZones(cluster_ref, api_error)
  File "/usr/lib/google-cloud-sdk/lib/googlecloudsdk/api_lib/container/api_adapter.py", line 1138, in CheckClusterOtherZones
    zone=cluster.zone))
googlecloudsdk.api_lib.container.util.Error: ResponseError: code=404, message=Not found: projects/cohesive-slate-308002/locations/us-east1/clusters/richard.
Could not find [richard] in [us-east1].
Did you mean [richard] in [us-east1-b]?
2021-04-16 16:28:20,568 ERROR    root            (gcloud.container.clusters.describe) ResponseError: code=404, message=Not found: projects/cohesive-slate-308002/locations/us-east1/clusters/richard.
Could not find [richard] in [us-east1].
Did you mean [richard] in [us-east1-b]?
